Workbook
Name Evalucion: 'Evalucion (2)'!$A$3:$EY$9
Name Evalucion: Evalucion!$A$1:$EZ$7

Sheet Hoja1 (2)
A1: # | B1: Cod Prod | C1: Producto | D1: Fabricante | E1: FAB | F1: USO | G1: fehca | H1: nsimple | I1: peligros físicos | J1: peligros para la salud | K1: peligros para el medio ambiente | L1: Clasificación peligro físico | M1: clasificación peligro para la salud | N1: Clasificación peligro para el medio | O1: Palabra de advertencia
A2: 1 | B2: PRODUCTO 1 - INDUSTRIAL - FABRICANTE 6 | C2: PINTURA ANTIDESLIZANTE PARA CANCHAS DEPORTIVAS | D2: TECNIDECOR | E2: FABRICANTE 6 | F2: Industrial | G2: 43374 | H2: PRODUCTO 1 | I2: 1 | J2: 1 | K2: 0 | L2: Líquidos Inflamables : Categoría 3 | M2: Irritación cutáneas : Categoría 2 | N2: No aplica | O2: Peligro | Q2: Domestica | R2: =COUNTIF(F:F,Q2) -> 25
A3: 2 | B3: PRODUCTO 1 - INDUSTRIAL - FABRICANTE 1 | C3: Corlar 2.8 HG Epóxico Alto Brillo - Base Media | D3: AXALTA | E3: FABRICANTE 1 | F3: Industrial | G3: 44094 | H3: PRODUCTO 1 | Q3: Industrial | R3: =COUNTIF(F:F,Q3) -> 25
A4: 3 | B4: PRODUCTO 1 - INDUSTRIAL - FABRICANTE 5 | C4: All Purpose Enamel Astro Blue Spray Paint | D4: CRC | E4: FABRICANTE 5 | F4: Industrial | G4: 42677 | H4: PRODUCTO 1 | S4: Industrial | T4: Domestica | W4: Industrial | X4: Domestica
A5: 4 | B5: PRODUCTO 2 - INDUSTRIAL - FABRICANTE 1 | C5: Tufcote 3.5 HH - Aluminum | D5: AXALTA | E5: FABRICANTE 1 | F5: Industrial | G5: 43889 | H5: PRODUCTO 2 | P5: AXALTA | Q5: FABRICANTE 1 | R5: =COUNTIF(E:E,Q5) -> 5 | S5: =COUNTIFS($E:$E,$Q5,$F:$F,S$4) -> 5 | T5: =COUNTIFS($E:$E,$Q5,$F:$F,T$4) -> 0 | U5: =SUM(S5:T5) -> 5 | W5: =S5/5 -> 1 | X5: =T5/5 -> 0
A6: 5 | B6: PRODUCTO 2 - INDUSTRIAL - FABRICANTE 6 | C6: CATALIZADOR EPOXICO | D6: TECNIDECOR | E6: FABRICANTE 6 | F6: Industrial | G6: 43374 | H6: PRODUCTO 2 | P6: RUST-OLEUM CORPORATION | Q6: FABRICANTE 2 | R6: =COUNTIF(E:E,Q6) -> 5 | S6: =COUNTIFS($E:$E,$Q6,$F:$F,S$4) -> 0 | T6: =COUNTIFS($E:$E,$Q6,$F:$F,T$4) -> 5 | U6: =SUM(S6:T6) -> 5 | W6: =S6/5 -> 0 | X6: =T6/5 -> 1
A7: 6 | B7: PRODUCTO 3 - INDUSTRIAL - FABRICANTE 1 | C7: UP ARMOUR YELLOW 10-C 9M02 | D7: AXALTA | E7: FABRICANTE 1 | F7: Industrial | G7: 43889 | H7: PRODUCTO 3 | P7: Pintuco | Q7: FABRICANTE 3 | R7: =COUNTIF(E:E,Q7) -> 10 | S7: =COUNTIFS($E:$E,$Q7,$F:$F,S$4) -> 5 | T7: =COUNTIFS($E:$E,$Q7,$F:$F,T$4) -> 5 | U7: =SUM(S7:T7) -> 10 | W7: =S7/5 -> 1 | X7: =T7/5 -> 1
A8: 7 | B8: PRODUCTO 1 - DOMESTICA - FABRICANTE 2 | C8: R-O QT 2PK LATAM CHALKED PAINT TIDAL PND | D8: RUST-OLEUM CORPORATION | E8: FABRICANTE 2 | F8: Domestica | G8: 43188 | H8: PRODUCTO 1 | P8: SIKA | Q8: FABRICANTE 4 | R8: =COUNTIF(E:E,Q8) -> 5 | S8: =COUNTIFS($E:$E,$Q8,$F:$F,S$4) -> 5 | T8: =COUNTIFS($E:$E,$Q8,$F:$F,T$4) -> 0 | U8: =SUM(S8:T8) -> 5 | W8: =S8/5 -> 1 | X8: =T8/5 -> 0
A9: 8 | B9: PRODUCTO 1 - DOMESTICA - FABRICANTE 6 | C9: ESMALTE POLIURETANO | D9: TECNIDECOR | E9: FABRICANTE 6 | F9: Domestica | G9: 43374 | H9: PRODUCTO 1 | P9: CRC | Q9: FABRICANTE 5 | R9: =COUNTIF(E:E,Q9) -> 5 | S9: =COUNTIFS($E:$E,$Q9,$F:$F,S$4) -> 5 | T9: =COUNTIFS($E:$E,$Q9,$F:$F,T$4) -> 0 | U9: =SUM(S9:T9) -> 5 | W9: =S9/5 -> 1 | X9: =T9/5 -> 0
A10: 9 | B10: PRODUCTO 2 - DOMESTICA - FABRICANTE 2 | C10: R-O QT 2PK LATAM CHALKED PAINT1 CHARCOAL | D10: RUST-OLEUM CORPORATION | E10: FABRICANTE 2 | F10: Domestica | G10: 43950 | H10: PRODUCTO 2 | P10: TECNIDECOR | Q10: FABRICANTE 6 | R10: =COUNTIF(E:E,Q10) -> 10 | S10: =COUNTIFS($E:$E,$Q10,$F:$F,S$4) -> 5 | T10: =COUNTIFS($E:$E,$Q10,$F:$F,T$4) -> 5 | U10: =SUM(S10:T10) -> 10 | W10: =S10/5 -> 1 | X10: =T10/5 -> 1
A11: 10 | B11: PRODUCTO 3 - INDUSTRIAL - FABRICANTE 6 | C11: CATALIZADOR DURAGLASS | D11: TECNIDECOR | E11: FABRICANTE 6 | F11: Industrial | G11: 43374 | H11: PRODUCTO 3 | P11: IEDISA | Q11: FABRICANTE 7 | R11: =COUNTIF(E:E,Q11) -> 5 | S11: =COUNTIFS($E:$E,$Q11,$F:$F,S$4) -> 0 | T11: =COUNTIFS($E:$E,$Q11,$F:$F,T$4) -> 5 | U11: =SUM(S11:T11) -> 5 | W11: =S11/5 -> 0 | X11: =T11/5 -> 1
A12: 11 | B12: PRODUCTO 1 - DOMESTICA - FABRICANTE 3 | C12: KORAZA BLANCO 2650 10015206-10016171 | D12: Pintuco | E12: FABRICANTE 3 | F12: Domestica | G12: 43551 | H12: PRODUCTO 1 | P12: INVESA | Q12: FABRICANTE 8 | R12: =COUNTIF(E:E,Q12) -> 5 | S12: =COUNTIFS($E:$E,$Q12,$F:$F,S$4) -> 0 | T12: =COUNTIFS($E:$E,$Q12,$F:$F,T$4) -> 5 | U12: =SUM(S12:T12) -> 5 | W12: =S12/5 -> 0 | X12: =T12/5 -> 1
A13: 12 | B13: PRODUCTO 2 - DOMESTICA - FABRICANTE 3 | C13: KORAZA NEGRO 20380 10016550 | D13: Pintuco | E13: FABRICANTE 3 | F13: Domestica | G13: 43493 | H13: PRODUCTO 2 | R13: =SUM(R5:R12) -> 50 | S13: =SUM(S5:S12) -> 25 | T13: =SUM(T5:T12) -> 25 | U13: =SUM(U5:U12) -> 50 | W13: =SUM(W5:W12) -> 5 | X13: =SUM(X5:X12) -> 5
A14: 13 | B14: PRODUCTO 3 - DOMESTICA - FABRICANTE 3 | C14: KORAZA PRO 550 BLANCO 10350789-10289257 | D14: Pintuco | E14: FABRICANTE 3 | F14: Domestica | G14: 43236 | H14: PRODUCTO 3
A15: 14 | B15: PRODUCTO 4 - DOMESTICA - FABRICANTE 3 | C15: PINTURA ANTICORROSIVA GRIS 507 10014333 | D15: Pintuco | E15: FABRICANTE 3 | F15: Domestica | G15: 43246 | H15: PRODUCTO 4
A16: 15 | B16: PRODUCTO 1 - INDUSTRIAL - FABRICANTE 3 | C16: PINTUTRAFICO ACRILICO BASE 1 G10115022 | D16: Pintuco | E16: FABRICANTE 3 | F16: Industrial | G16: 43101 | H16: PRODUCTO 1
A17: 16 | B17: PRODUCTO 2 - INDUSTRIAL - FABRICANTE 3 | C17: PINTUTRAFICO ALQUIDICO AMARILLO 659 10012970 | D17: Pintuco | E17: FABRICANTE 3 | F17: Industrial | G17: 43321 | H17: PRODUCTO 2
A18: 17 | B18: PRODUCTO 2 - DOMESTICA - FABRICANTE 6 | C18: OXIGEL | D18: TECNIDECOR | E18: FABRICANTE 6 | F18: Domestica | G18: 43374 | H18: PRODUCTO 2
A19: 18 | B19: PRODUCTO 3 - INDUSTRIAL - FABRICANTE 3 | C19: PINTURA EPOXI POLIAMIDA BLANCO 13243 | D19: Pintuco | E19: FABRICANTE 3 | F19: Industrial | G19: 43236 | H19: PRODUCTO 3
A20: 19 | B20: PRODUCTO 3 - DOMESTICA - FABRICANTE 2 | C20: R-O QT 2PK LATAM CHALKED PAINT LINEN WHT | D20: RUST-OLEUM CORPORATION | E20: FABRICANTE 2 | F20: Domestica | G20: 43950 | H20: PRODUCTO 3
A21: 20 | B21: PRODUCTO 4 - INDUSTRIAL - FABRICANTE 3 | C21: ESMALTE AROFLEX BLANCO 2901 10012888 | D21: Pintuco | E21: FABRICANTE 3 | F21: Industrial | G21: 43236 | H21: PRODUCTO 4
A22: 21 | B22: PRODUCTO 4 - DOMESTICA - FABRICANTE 2 | C22: R-O QT 2PK LATAM CHALKED PAINT CHARCOAL | D22: RUST-OLEUM CORPORATION | E22: FABRICANTE 2 | F22: Domestica | G22: 43950 | H22: PRODUCTO 4
A23: 22 | B23: PRODUCTO 1 - DOMESTICA - FABRICANTE 8 | C23: Esmaltes alquídicos de secado al aire | E23: FABRICANTE 8 | F23: Domestica | G23: 43503 | H23: PRODUCTO 1
A24: 23 | B24: PRODUCTO 1 - DOMESTICA - FABRICANTE 7 | C24: GrafClean FRONT Premium | D24: IEDISA | E24: FABRICANTE 7 | F24: Domestica | G24: 43466 | H24: PRODUCTO 1
A25: 24 | B25: PRODUCTO 2 - DOMESTICA - FABRICANTE 7 | C25: Ecosphere Premium | D25: IEDISA | E25: FABRICANTE 7 | F25: Domestica | G25: 43101 | H25: PRODUCTO 2
A26: 25 | B26: PRODUCTO 4 - INDUSTRIAL - FABRICANTE 1 | C26: 3615SM 19LT CONVERTIDOR UNIVERSAL | D26: AXALTA | E26: FABRICANTE 1 | F26: Industrial | G26: 43834 | H26: PRODUCTO 4
A27: 26 | B27: PRODUCTO 1 - INDUSTRIAL - FABRICANTE 4 | C27: Esmalte Uretano Comp. A | D27: SIKA | E27: FABRICANTE 4 | F27: Industrial | G27: 43472 | H27: PRODUCTO 1
A28: 27 | B28: PRODUCTO 5 - INDUSTRIAL - FABRICANTE 1 | C28: IW140 .750L TRANSPARENTE KRISTALITY | D28: AXALTA | E28: FABRICANTE 1 | F28: Industrial | G28: 43987 | H28: PRODUCTO 5
A29: 28 | B29: PRODUCTO 5 - DOMESTICA - FABRICANTE 2 | C29: R-O QT 2PK LATAM CHALKED PAINT B CORAL | D29: RUST-OLEUM CORPORATION | E29: FABRICANTE 2 | F29: Domestica | G29: 43843 | H29: PRODUCTO 5
A30: 29 | B30: PRODUCTO 5 - INDUSTRIAL - FABRICANTE 3 | C30: PINTURA PARA TRAFICO ACRILICO BASE SOLVENTE BLANCO 13722 10017277-10015687 | D30: Pintuco | E30: FABRICANTE 3 | F30: Industrial | G30: 43493 | H30: PRODUCTO 5
A31: 30 | B31: PRODUCTO 5 - DOMESTICA - FABRICANTE 3 | C31: PINTURA ANTICORROSIVA GRIS 507 10014333-10012454-10171712 | D31: Pintuco | E31: FABRICANTE 3 | F31: Domestica | G31: 43236 | H31: PRODUCTO 5
A32: 31 | B32: PRODUCTO 2 - INDUSTRIAL - FABRICANTE 4 | C32: Esmalte Alquídico Serie 31 | D32: SIKA | E32: FABRICANTE 4 | F32: Industrial | G32: 43612 | H32: PRODUCTO 2
A33: 32 | B33: PRODUCTO 3 - INDUSTRIAL - FABRICANTE 4 | C33: Esmalte Epóxico Aluminio | D33: SIKA | E33: FABRICANTE 4 | F33: Industrial | G33: 44111 | H33: PRODUCTO 3
A34: 33 | B34: PRODUCTO 4 - INDUSTRIAL - FABRICANTE 4 | C34: Epoxi 100HS Serie 300 Comp. A | D34: SIKA | E34: FABRICANTE 4 | F34: Industrial | G34: 43928 | H34: PRODUCTO 4
A35: 34 | B35: PRODUCTO 5 - INDUSTRIAL - FABRICANTE 4 | C35: SikaWall®-401 Pintura Texturizada | D35: SIKA | E35: FABRICANTE 4 | F35: Industrial | G35: 43989 | H35: PRODUCTO 5
... A43: 42 | B43: PRODUCTO 5 - DOMESTICA - FABRICANTE 7 | C43: GCS Exterior Premium - Base Pastel | D43: IEDISA | E43: FABRICANTE 7 | F43: Domestica | G43: 43101 | H43: PRODUCTO 5
A44: 43 | B44: PRODUCTO 2 - DOMESTICA - FABRICANTE 8 | C44: PINTURA EN AEROSOL SAPOLIN | E44: FABRICANTE 8 | F44: Domestica | G44: 43137 | H44: PRODUCTO 2
A45: 44 | B45: PRODUCTO 3 - DOMESTICA - FABRICANTE 8 | C45: Pintura tráfico base agua | E45: FABRICANTE 8 | F45: Domestica | G45: 43692 | H45: PRODUCTO 3
A46: 45 | B46: PRODUCTO 4 - DOMESTICA - FABRICANTE 8 | C46: VINICRYL | E46: FABRICANTE 8 | F46: Domestica | G46: 43539 | H46: PRODUCTO 4
A47: 46 | B47: PRODUCTO 5 - DOMESTICA - FABRICANTE 8 | C47: THINNER | E47: FABRICANTE 8 | F47: Domestica | G47: 43699 | H47: PRODUCTO 5
...

Sheet Hoja1

Sheet Hoja2

Sheet Hoja3

Sheet Hoja4

Sheet Datos
A1: Id | B1: Nombre del Producto | C1: Fabricante | D1: Fecha Elaboración | E1: Criterios | F1: Item_1_0 | G1: Calidad_1_0 | H1: Item_1_1 | I1: Calidad_1_1 | J1: Item_1_2 | K1: Calidad_1_2 | L1: Item_1_3 | M1: Calidad_1_3 | N1: Item_1_4 | O1: Calidad_1_4 | P1: Item_1_5 | Q1: Calidad_1_5 | R1: Item_2_0 | S1: Calidad_2_0 | T1: Item_2_1 | U1: Calidad_2_1 | V1: Item_2_1_1 | W1: Calidad_2_1_1 | X1: Item_2_1_2 | Y1: Calidad_2_1_2 | Z1: Item_2_1_3 | AA1: Calidad_2_1_3 | AB1: Item_2_1_4 | AC1: Calidad_2_1_4 | AD1: Item_2_2 | AE1: Calidad_2_2 | AF1: Item_3_0 | AG1: Calidad_3_0 | AH1: Item_3_1_1 | AI1: Calidad_3_1_1 | AJ1: Item_3_1_1_1 | AK1: Calidad_3_1_1_1 | AL1: Item_3_1_1_2 | AM1: Calidad_3_1_1_2 | AN1: Item_3_1_1_3 | AO1: Calidad_3_1_1_3 | AP1: Item_3_2_1 | AQ1: Calidad_3_2_1 | AR1: Item_3_2_1_1 | AS1: Calidad_3_2_1_1 | AT1: Item_3_2_1_2 | AU1: Calidad_3_2_1_2 | AV1: Calidad_3_5 | AW1: Item_3_2_1_3 | AX1: Calidad_3_2_1_3 | AY1: Item_4_0 | AZ1: Calidad_4_0 | BA1: Item_4_1 | BB1: Calidad_4_1 | BC1: Item_4_2 | BD1: Calidad_4_2 | BE1: Item_4_3 | BF1: Calidad_4_3 | BG1: Item_5_0 | BH1: Calidad_5_0 | BI1: Item_5_1 | BJ1: Calidad_5_1 | BK1: Item_5_2 | BL1: Calidad_5_2 | BM1: Item_5_3 | BN1: Calidad_5_3 | BO1: Item_6_0 | BP1: Calidad_6_0 | BQ1: Item_6_1 | BR1: Calidad_6_1 | BS1: Item_6_2 | BT1: Calidad_6_2 | BU1: Item_6_3 | BV1: Calidad_6_3 | BW1: Item_7_0 | BX1: Calidad_7_0 | BY1: Item_7_1 | BZ1: Calidad_7_1 | CA1: Item_7_2 | CB1: Calidad_7_2 | CC1: Item_8_0 | CD1: Calidad_8_0 | CE1: Item_8_1 | CF1: Calidad_8_1 | CG1: Item_8_2 | CH1: Calidad_8_2 | CI1: Item_8_3 | CJ1: Calidad_8_3 | CK1: Item_9_0 | CL1: Calidad_9_0 | CM1: Item_9_1 | CN1: Calidad_9_1 | CO1: Item_10_0 | CP1: Calidad_10_0 | CQ1: Item_10_2_1 | CR1: Calidad_10_2_1 | CS1: Item_10_2_2 | CT1: Calidad_10_2_2 | CU1: Item_10_2_3 | CV1: Calidad_10_2_3 | CW1: Item_10_2_4 | CX1: Calidad_10_2_4 | CY1: Item_10_2_5 | CZ1: Calidad_10_2_5 | DA1: Item_10_2_6 | DB1: Calidad_10_2_6 | DC1: Item_11_0 | DD1: Calidad_11_0 | DE1: Item_11_1 | DF1: Calidad_11_1 | DG1: Item_11_2 | DH1: Calidad_11_2 | DI1: Item_11_3 | DJ1: Calidad_11_3 | DK1: Item_11_4 | DL1: Calidad_11_4 | DM1: Item_11_5 | DN1: Calidad_11_5 | DO1: Item_12_0 | DP1: Calidad_12_0 | DQ1: Item_12_1 | DR1: Calidad_12_1 | DS1: Item_12_2 | DT1: Calidad_12_2 | DU1: Item_12_3 | DV1: Calidad_12_3 | DW1: Item_12_4 | DX1: Calidad_12_4 | DY1: Item_12_5 | DZ1: Calidad_12_5 | EA1: Item_13_0 | EB1: Calidad_13_0 | EC1: Item_13_1 | ED1: Calidad_13_1 | EE1: Item_14_0 | EF1: Calidad_14_0 | EG1: Item_14_1 | EH1: Calidad_14_1 | EI1: Item_14_2 | EJ1: Calidad_14_2 | EK1: Item_14_3 | EL1: Calidad_14_3 | EM1: Item_14_4 | EN1: Calidad_14_4 | EO1: Item_14_5 | EP1: Calidad_14_5 | EQ1: Item_14_6 | ER1: Calidad_14_6 | ES1: Item_15_0 | ET1: Calidad_15_0 | EU1: Item_15_1 | EV1: Calidad_15_1 | EW1: Item_16_0 | EX1: Calidad_16_0 | EY1: Item_16_1 | EZ1: Calidad_16_1
E2: Presente | F2: =COUNTIF(Evalucion!F:F,$E2)/F$7 -> 1 | G2: =COUNTIF(Evalucion!G:G,$E2)/G$7 -> 0 | H2: =COUNTIF(Evalucion!H:H,$E2)/H$7 -> 0.8 | I2: =COUNTIF(Evalucion!I:I,$E2)/I$7 -> 0 | J2: =COUNTIF(Evalucion!J:J,$E2)/J$7 -> 0.46 | K2: =COUNTIF(Evalucion!K:K,$E2)/K$7 -> 0 | L2: =COUNTIF(Evalucion!L:L,$E2)/L$7 -> 0.8 | M2: =COUNTIF(Evalucion!M:M,$E2)/M$7 -> 0 | N2: =COUNTIF(Evalucion!N:N,$E2)/N$7 -> 1 | O2: =COUNTIF(Evalucion!O:O,$E2)/O$7 -> 0 | P2: =COUNTIF(Evalucion!P:P,$E2)/P$7 -> 0.8 | Q2: =COUNTIF(Evalucion!Q:Q,$E2)/Q$7 -> 0 | R2: =COUNTIF(Evalucion!R:R,$E2)/R$7 -> 1 | S2: =COUNTIF(Evalucion!S:S,$E2)/S$7 -> 0 | T2: =COUNTIF(Evalucion!T:T,$E2)/T$7 -> 0.64 | U2: =COUNTIF(Evalucion!U:U,$E2)/U$7 -> 0 | V2: =COUNTIF(Evalucion!V:V,$E2)/V$7 -> 0.66 | W2: =COUNTIF(Evalucion!W:W,$E2)/W$7 -> 0 | X2: =COUNTIF(Evalucion!X:X,$E2)/X$7 -> 0.64 | Y2: =COUNTIF(Evalucion!Y:Y,$E2)/Y$7 -> 0 | Z2: =COUNTIF(Evalucion!Z:Z,$E2)/Z$7 -> 0.66 | AA2: =COUNTIF(Evalucion!AA:AA,$E2)/AA$7 -> 0 | AB2: =COUNTIF(Evalucion!AB:AB,$E2)/AB$7 -> 0.64 | AC2: =COUNTIF(Evalucion!AC:AC,$E2)/AC$7 -> 0 | AD2: =COUNTIF(Evalucion!AD:AD,$E2)/AD$7 -> 0.84 | AE2: =COUNTIF(Evalucion!AE:AE,$E2)/AE$7 -> 0 | AF2: =COUNTIF(Evalucion!AF:AF,$E2)/AF$7 -> 1 | AG2: =COUNTIF(Evalucion!AG:AG,$E2)/AG$7 -> 0 | AH2: =COUNTIF(Evalucion!AH:AH,$E2)/AH$7 -> #DIV/0! | AI2: =COUNTIF(Evalucion!AI:AI,$E2)/AI$7 -> #DIV/0! | AJ2: =COUNTIF(Evalucion!AJ:AJ,$E2)/AJ$7 -> #DIV/0! | AK2: =COUNTIF(Evalucion!AK:AK,$E2)/AK$7 -> #DIV/0! | AL2: =COUNTIF(Evalucion!AL:AL,$E2)/AL$7 -> #DIV/0! | AM2: =COUNTIF(Evalucion!AM:AM,$E2)/AM$7 -> #DIV/0! | AN2: =COUNTIF(Evalucion!AN:AN,$E2)/AN$7 -> #DIV/0! | AO2: =COUNTIF(Evalucion!AO:AO,$E2)/AO$7 -> #DIV/0! | AP2: =COUNTIF(Evalucion!AP:AP,$E2)/AP$7 -> 1 | AQ2: =COUNTIF(Evalucion!AQ:AQ,$E2)/AQ$7 -> 0 | AR2: =COUNTIF(Evalucion!AR:AR,$E2)/AR$7 -> 0.1 | AS2: =COUNTIF(Evalucion!AS:AS,$E2)/AS$7 -> 0 | AT2: =COUNTIF(Evalucion!AT:AT,$E2)/AT$7 -> 0.76 | AU2: =COUNTIF(Evalucion!AU:AU,$E2)/AU$7 -> 0 | AV2: =COUNTIF(Evalucion!AV:AV,$E2)/AV$7 -> #DIV/0! | AW2: =COUNTIF(Evalucion!AW:AW,$E2)/AW$7 -> 0.56 | AX2: =COUNTIF(Evalucion!AX:AX,$E2)/AX$7 -> 0 | AY2: =COUNTIF(Evalucion!AY:AY,$E2)/AY$7 -> 1 | AZ2: =COUNTIF(Evalucion!AZ:AZ,$E2)/AZ$7 -> 0 | BA2: =COUNTIF(Evalucion!BA:BA,$E2)/BA$7 -> 1 | BB2: =COUNTIF(Evalucion!BB:BB,$E2)/BB$7 -> 0 | BC2: =COUNTIF(Evalucion!BC:BC,$E2)/BC$7 -> 0.7 | BD2: =COUNTIF(Evalucion!BD:BD,$E2)/BD$7 -> 0 | BE2: =COUNTIF(Evalucion!BE:BE,$E2)/BE$7 -> 0.7 | BF2: =COUNTIF(Evalucion!BF:BF,$E2)/BF$7 -> 0 | BG2: =COUNTIF(Evalucion!BG:BG,$E2)/BG$7 -> 1 | BH2: =COUNTIF(Evalucion!BH:BH,$E2)/BH$7 -> 0 | BI2: =COUNTIF(Evalucion!BI:BI,$E2)/BI$7 -> 0.8 | BJ2: =COUNTIF(Evalucion!BJ:BJ,$E2)/BJ$7 -> 0 | BK2: =COUNTIF(Evalucion!BK:BK,$E2)/BK$7 -> 0.68 | BL2: =COUNTIF(Evalucion!BL:BL,$E2)/BL$7 -> 0 | BM2: =COUNTIF(Evalucion!BM:BM,$E2)/BM$7 -> 0.6 | BN2: =COUNTIF(Evalucion!BN:BN,$E2)/BN$7 -> 0 | BO2: =COUNTIF(Evalucion!BO:BO,$E2)/BO$7 -> 1 | BP2: =COUNTIF(Evalucion!BP:BP,$E2)/BP$7 -> 0 | BQ2: =COUNTIF(Evalucion!BQ:BQ,$E2)/BQ$7 -> 0.6 | BR2: =COUNTIF(Evalucion!BR:BR,$E2)/BR$7 -> 0 | BS2: =COUNTIF(Evalucion!BS:BS,$E2)/BS$7 -> 0.56 | BT2: =COUNTIF(Evalucion!BT:BT,$E2)/BT$7 -> 0 | BU2: =COUNTIF(Evalucion!BU:BU,$E2)/BU$7 -> 0.7 | BV2: =COUNTIF(Evalucion!BV:BV,$E2)/BV$7 -> 0 | BW2: =COUNTIF(Evalucion!BW:BW,$E2)/BW$7 -> 1 | BX2: =COUNTIF(Evalucion!BX:BX,$E2)/BX$7 -> 0 | BY2: =COUNTIF(Evalucion!BY:BY,$E2)/BY$7 -> 0.7 | BZ2: =COUNTIF(Evalucion!BZ:BZ,$E2)/BZ$7 -> 0 | CA2: =COUNTIF(Evalucion!CA:CA,$E2)/CA$7 -> 0.6 | CB2: =COUNTIF(Evalucion!CB:CB,$E2)/CB$7 -> 0 | CC2: =COUNTIF(Evalucion!CC:CC,$E2)/CC$7 -> 1 | CD2: =COUNTIF(Evalucion!CD:CD,$E2)/CD$7 -> 0 | CE2: =COUNTIF(Evalucion!CE:CE,$E2)/CE$7 -> 1 | CF2: =COUNTIF(Evalucion!CF:CF,$E2)/CF$7 -> 0 | CG2: =COUNTIF(Evalucion!CG:CG,$E2)/CG$7 -> 0.6 | CH2: =COUNTIF(Evalucion!CH:CH,$E2)/CH$7 -> 0 | CI2: =COUNTIF(Evalucion!CI:CI,$E2)/CI$7 -> 0.78 | CJ2: =COUNTIF(Evalucion!CJ:CJ,$E2)/CJ$7 -> 0 | CK2: =COUNTIF(Evalucion!CK:CK,$E2)/CK$7 -> 1 | CL2: =COUNTIF(Evalucion!CL:CL,$E2)/CL$7 -> 0 | CM2: =COUNTIF(Evalucion!CM:CM,$E2)/CM$7 -> 1 | CN2: =COUNTIF(Evalucion!CN:CN,$E2)/CN$7 -> 0 | CO2: =COUNTIF(Evalucion!CO:CO,$E2)/CO$7 -> 1 | CP2: =COUNTIF(Evalucion!CP:CP,$E2)/CP$7 -> 0 | CQ2: =COUNTIF(Evalucion!CQ:CQ,$E2)/CQ$7 -> 0.62 | CR2: =COUNTIF(Evalucion!CR:CR,$E2)/CR$7 -> 0 | CS2: =COUNTIF(Evalucion!CS:CS,$E2)/CS$7 -> 0.78 | CT2: =COUNTIF(Evalucion!CT:CT,$E2)/CT$7 -> 0 | CU2: =COUNTIF(Evalucion!CU:CU,$E2)/CU$7 -> 0.6 | CV2: =COUNTIF(Evalucion!CV:CV,$E2)/CV$7 -> 0 | CW2: =COUNTIF(Evalucion!CW:CW,$E2)/CW$7 -> 0.96 | CX2: =COUNTIF(Evalucion!CX:CX,$E2)/CX$7 -> 0 | CY2: =COUNTIF(Evalucion!CY:CY,$E2)/CY$7 -> 0.9 | CZ2: =COUNTIF(Evalucion!CZ:CZ,$E2)/CZ$7 -> 0 | DA2: =COUNTIF(Evalucion!DA:DA,$E2)/DA$7 -> 0.84 | DB2: =COUNTIF(Evalucion!DB:DB,$E2)/DB$7 -> 0 | DC2: =COUNTIF(Evalucion!DC:DC,$E2)/DC$7 -> 1 | DD2: =COUNTIF(Evalucion!DD:DD,$E2)/DD$7 -> 0 | DE2: =COUNTIF(Evalucion!DE:DE,$E2)/DE$7 -> 0.28 | DF2: =COUNTIF(Evalucion!DF:DF,$E2)/DF$7 -> 0 | DG2: =COUNTIF(Evalucion!DG:DG,$E2)/DG$7 -> 0.98 | DH2: =COUNTIF(Evalucion!DH:DH,$E2)/DH$7 -> 0 | DI2: =COUNTIF(Evalucion!DI:DI,$E2)/DI$7 -> 0.3 | DJ2: =COUNTIF(Evalucion!DJ:DJ,$E2)/DJ$7 -> 0 | DK2: =COUNTIF(Evalucion!DK:DK,$E2)/DK$7 -> 0.28 | DL2: =COUNTIF(Evalucion!DL:DL,$E2)/DL$7 -> 0 | DM2: =COUNTIF(Evalucion!DM:DM,$E2)/DM$7 -> 0.52 | DN2: =COUNTIF(Evalucion!DN:DN,$E2)/DN$7 -> 0 | DO2: =COUNTIF(Evalucion!DO:DO,$E2)/DO$7 -> 1 | DP2: =COUNTIF(Evalucion!DP:DP,$E2)/DP$7 -> 0 | DQ2: =COUNTIF(Evalucion!DQ:DQ,$E2)/DQ$7 -> 0.84 | DR2: =COUNTIF(Evalucion!DR:DR,$E2)/DR$7 -> 0 | DS2: =COUNTIF(Evalucion!DS:DS,$E2)/DS$7 -> 0.54 | DT2: =COUNTIF(Evalucion!DT:DT,$E2)/DT$7 -> 0 | DU2: =COUNTIF(Evalucion!DU:DU,$E2)/DU$7 -> 0.84 | DV2: =COUNTIF(Evalucion!DV:DV,$E2)/DV$7 -> 0 | DW2: =COUNTIF(Evalucion!DW:DW,$E2)/DW$7 -> 0.54 | DX2: =COUNTIF(Evalucion!DX:DX,$E2)/DX$7 -> 0 | DY2: =COUNTIF(Evalucion!DY:DY,$E2)/DY$7 -> 0.54 | DZ2: =COUNTIF(Evalucion!DZ:DZ,$E2)/DZ$7 -> 0 | EA2: =COUNTIF(Evalucion!EA:EA,$E2)/EA$7 -> 1 | EB2: =COUNTIF(Evalucion!EB:EB,$E2)/EB$7 -> 0 | EC2: =COUNTIF(Evalucion!EC:EC,$E2)/EC$7 -> 0.8 | ED2: =COUNTIF(Evalucion!ED:ED,$E2)/ED$7 -> 0 | EE2: =COUNTIF(Evalucion!EE:EE,$E2)/EE$7 -> 1 | EF2: =COUNTIF(Evalucion!EF:EF,$E2)/EF$7 -> 0 | EG2: =COUNTIF(Evalucion!EG:EG,$E2)/EG$7 -> 0.88 | EH2: =COUNTIF(Evalucion!EH:EH,$E2)/EH$7 -> 0 | EI2: =COUNTIF(Evalucion!EI:EI,$E2)/EI$7 -> 0.58 | EJ2: =COUNTIF(Evalucion!EJ:EJ,$E2)/EJ$7 -> 0 | EK2: =COUNTIF(Evalucion!EK:EK,$E2)/EK$7 -> 0.68 | EL2: =COUNTIF(Evalucion!EL:EL,$E2)/EL$7 -> 0 | EM2: =COUNTIF(Evalucion!EM:EM,$E2)/EM$7 -> 0.88 | EN2: =COUNTIF(Evalucion!EN:EN,$E2)/EN$7 -> 0 | EO2: =COUNTIF(Evalucion!EO:EO,$E2)/EO$7 -> 0.48 | EP2: =COUNTIF(Evalucion!EP:EP,$E2)/EP$7 -> 0 | EQ2: =COUNTIF(Evalucion!EQ:EQ,$E2)/EQ$7 -> 0.48 | ER2: =COUNTIF(Evalucion!ER:ER,$E2)/ER$7 -> 0 | ES2: =COUNTIF(Evalucion!ES:ES,$E2)/ES$7 -> 1 | ET2: =COUNTIF(Evalucion!ET:ET,$E2)/ET$7 -> 0 | EU2: =COUNTIF(Evalucion!EU:EU,$E2)/EU$7 -> 0.98 | EV2: =COUNTIF(Evalucion!EV:EV,$E2)/EV$7 -> 0 | EW2: =COUNTIF(Evalucion!EW:EW,$E2)/EW$7 -> 1 | EX2: =COUNTIF(Evalucion!EX:EX,$E2)/EX$7 -> 0 | EY2: =COUNTIF(Evalucion!EY:EY,$E2)/EY$7 -> 1 | EZ2: =COUNTIF(Evalucion!EZ:EZ,$E2)/EZ$7 -> 0
E3: No Present | F3: =COUNTIF(Evalucion!F:F,$E3)/F$7 -> 0 | G3: =COUNTIF(Evalucion!G:G,$E3)/G$7 -> 0 | H3: =COUNTIF(Evalucion!H:H,$E3)/H$7 -> 0.2 | I3: =COUNTIF(Evalucion!I:I,$E3)/I$7 -> 0 | J3: =COUNTIF(Evalucion!J:J,$E3)/J$7 -> 0.54 | K3: =COUNTIF(Evalucion!K:K,$E3)/K$7 -> 0 | L3: =COUNTIF(Evalucion!L:L,$E3)/L$7 -> 0.2 | M3: =COUNTIF(Evalucion!M:M,$E3)/M$7 -> 0 | N3: =COUNTIF(Evalucion!N:N,$E3)/N$7 -> 0 | O3: =COUNTIF(Evalucion!O:O,$E3)/O$7 -> 0 | P3: =COUNTIF(Evalucion!P:P,$E3)/P$7 -> 0.2 | Q3: =COUNTIF(Evalucion!Q:Q,$E3)/Q$7 -> 0 | R3: =COUNTIF(Evalucion!R:R,$E3)/R$7 -> 0 | S3: =COUNTIF(Evalucion!S:S,$E3)/S$7 -> 0 | T3: =COUNTIF(Evalucion!T:T,$E3)/T$7 -> 0.36 | U3: =COUNTIF(Evalucion!U:U,$E3)/U$7 -> 0 | V3: =COUNTIF(Evalucion!V:V,$E3)/V$7 -> 0.34 | W3: =COUNTIF(Evalucion!W:W,$E3)/W$7 -> 0 | X3: =COUNTIF(Evalucion!X:X,$E3)/X$7 -> 0.36 | Y3: =COUNTIF(Evalucion!Y:Y,$E3)/Y$7 -> 0 | Z3: =COUNTIF(Evalucion!Z:Z,$E3)/Z$7 -> 0.34 | AA3: =COUNTIF(Evalucion!AA:AA,$E3)/AA$7 -> 0 | AB3: =COUNTIF(Evalucion!AB:AB,$E3)/AB$7 -> 0.36 | AC3: =COUNTIF(Evalucion!AC:AC,$E3)/AC$7 -> 0 | AD3: =COUNTIF(Evalucion!AD:AD,$E3)/AD$7 -> 0.16 | AE3: =COUNTIF(Evalucion!AE:AE,$E3)/AE$7 -> 0 | AF3: =COUNTIF(Evalucion!AF:AF,$E3)/AF$7 -> 0 | AG3: =COUNTIF(Evalucion!AG:AG,$E3)/AG$7 -> 0 | AH3: =COUNTIF(Evalucion!AH:AH,$E3)/AH$7 -> #DIV/0! | AI3: =COUNTIF(Evalucion!AI:AI,$E3)/AI$7 -> #DIV/0! | AJ3: =COUNTIF(Evalucion!AJ:AJ,$E3)/AJ$7 -> #DIV/0! | AK3: =COUNTIF(Evalucion!AK:AK,$E3)/AK$7 -> #DIV/0! | AL3: =COUNTIF(Evalucion!AL:AL,$E3)/AL$7 -> #DIV/0! | AM3: =COUNTIF(Evalucion!AM:AM,$E3)/AM$7 -> #DIV/0! | AN3: =COUNTIF(Evalucion!AN:AN,$E3)/AN$7 -> #DIV/0! | AO3: =COUNTIF(Evalucion!AO:AO,$E3)/AO$7 -> #DIV/0! | AP3: =COUNTIF(Evalucion!AP:AP,$E3)/AP$7 -> 0 | AQ3: =COUNTIF(Evalucion!AQ:AQ,$E3)/AQ$7 -> 0 | AR3: =COUNTIF(Evalucion!AR:AR,$E3)/AR$7 -> 0.9 | AS3: =COUNTIF(Evalucion!AS:AS,$E3)/AS$7 -> 0 | AT3: =COUNTIF(Evalucion!AT:AT,$E3)/AT$7 -> 0.24 | AU3: =COUNTIF(Evalucion!AU:AU,$E3)/AU$7 -> 0 | AV3: =COUNTIF(Evalucion!AV:AV,$E3)/AV$7 -> #DIV/0! | AW3: =COUNTIF(Evalucion!AW:AW,$E3)/AW$7 -> 0.44 | AX3: =COUNTIF(Evalucion!AX:AX,$E3)/AX$7 -> 0 | AY3: =COUNTIF(Evalucion!AY:AY,$E3)/AY$7 -> 0 | AZ3: =COUNTIF(Evalucion!AZ:AZ,$E3)/AZ$7 -> 0 | BA3: =COUNTIF(Evalucion!BA:BA,$E3)/BA$7 -> 0 | BB3: =COUNTIF(Evalucion!BB:BB,$E3)/BB$7 -> 0 | BC3: =COUNTIF(Evalucion!BC:BC,$E3)/BC$7 -> 0.3 | BD3: =COUNTIF(Evalucion!BD:BD,$E3)/BD$7 -> 0 | BE3: =COUNTIF(Evalucion!BE:BE,$E3)/BE$7 -> 0.3 | BF3: =COUNTIF(Evalucion!BF:BF,$E3)/BF$7 -> 0 | BG3: =COUNTIF(Evalucion!BG:BG,$E3)/BG$7 -> 0 | BH3: =COUNTIF(Evalucion!BH:BH,$E3)/BH$7 -> 0 | BI3: =COUNTIF(Evalucion!BI:BI,$E3)/BI$7 -> 0.2 | BJ3: =COUNTIF(Evalucion!BJ:BJ,$E3)/BJ$7 -> 0 | BK3: =COUNTIF(Evalucion!BK:BK,$E3)/BK$7 -> 0.32 | BL3: =COUNTIF(Evalucion!BL:BL,$E3)/BL$7 -> 0 | BM3: =COUNTIF(Evalucion!BM:BM,$E3)/BM$7 -> 0.4 | BN3: =COUNTIF(Evalucion!BN:BN,$E3)/BN$7 -> 0 | BO3: =COUNTIF(Evalucion!BO:BO,$E3)/BO$7 -> 0 | BP3: =COUNTIF(Evalucion!BP:BP,$E3)/BP$7 -> 0 | BQ3: =COUNTIF(Evalucion!BQ:BQ,$E3)/BQ$7 -> 0.4 | BR3: =COUNTIF(Evalucion!BR:BR,$E3)/BR$7 -> 0 | BS3: =COUNTIF(Evalucion!BS:BS,$E3)/BS$7 -> 0.44 | BT3: =COUNTIF(Evalucion!BT:BT,$E3)/BT$7 -> 0 | BU3: =COUNTIF(Evalucion!BU:BU,$E3)/BU$7 -> 0.3 | BV3: =COUNTIF(Evalucion!BV:BV,$E3)/BV$7 -> 0 | BW3: =COUNTIF(Evalucion!BW:BW,$E3)/BW$7 -> 0 | BX3: =COUNTIF(Evalucion!BX:BX,$E3)/BX$7 -> 0 | BY3: =COUNTIF(Evalucion!BY:BY,$E3)/BY$7 -> 0.3 | BZ3: =COUNTIF(Evalucion!BZ:BZ,$E3)/BZ$7 -> 0 | CA3: =COUNTIF(Evalucion!CA:CA,$E3)/CA$7 -> 0.4 | CB3: =COUNTIF(Evalucion!CB:CB,$E3)/CB$7 -> 0 | CC3: =COUNTIF(Evalucion!CC:CC,$E3)/CC$7 -> 0 | CD3: =COUNTIF(Evalucion!CD:CD,$E3)/CD$7 -> 0 | CE3: =COUNTIF(Evalucion!CE:CE,$E3)/CE$7 -> 0 | CF3: =COUNTIF(Evalucion!CF:CF,$E3)/CF$7 -> 0 | CG3: =COUNTIF(Evalucion!CG:CG,$E3)/CG$7 -> 0.4 | CH3: =COUNTIF(Evalucion!CH:CH,$E3)/CH$7 -> 0 | CI3: =COUNTIF(Evalucion!CI:CI,$E3)/CI$7 -> 0.22 | CJ3: =COUNTIF(Evalucion!CJ:CJ,$E3)/CJ$7 -> 0 | CK3: =COUNTIF(Evalucion!CK:CK,$E3)/CK$7 -> 0 | CL3: =COUNTIF(Evalucion!CL:CL,$E3)/CL$7 -> 0 | CM3: =COUNTIF(Evalucion!CM:CM,$E3)/CM$7 -> 0 | CN3: =COUNTIF(Evalucion!CN:CN,$E3)/CN$7 -> 0 | CO3: =COUNTIF(Evalucion!CO:CO,$E3)/CO$7 -> 0 | CP3: =COUNTIF(Evalucion!CP:CP,$E3)/CP$7 -> 0 | CQ3: =COUNTIF(Evalucion!CQ:CQ,$E3)/CQ$7 -> 0.38 | CR3: =COUNTIF(Evalucion!CR:CR,$E3)/CR$7 -> 0 | CS3: =COUNTIF(Evalucion!CS:CS,$E3)/CS$7 -> 0.22 | CT3: =COUNTIF(Evalucion!CT:CT,$E3)/CT$7 -> 0 | CU3: =COUNTIF(Evalucion!CU:CU,$E3)/CU$7 -> 0.4 | CV3: =COUNTIF(Evalucion!CV:CV,$E3)/CV$7 -> 0 | CW3: =COUNTIF(Evalucion!CW:CW,$E3)/CW$7 -> 0.04 | CX3: =COUNTIF(Evalucion!CX:CX,$E3)/CX$7 -> 0 | CY3: =COUNTIF(Evalucion!CY:CY,$E3)/CY$7 -> 0.1 | CZ3: =COUNTIF(Evalucion!CZ:CZ,$E3)/CZ$7 -> 0 | DA3: =COUNTIF(Evalucion!DA:DA,$E3)/DA$7 -> 0.16 | DB3: =COUNTIF(Evalucion!DB:DB,$E3)/DB$7 -> 0 | DC3: =COUNTIF(Evalucion!DC:DC,$E3)/DC$7 -> 0 | DD3: =COUNTIF(Evalucion!DD:DD,$E3)/DD$7 -> 0 | DE3: =COUNTIF(Evalucion!DE:DE,$E3)/DE$7 -> 0.72 | DF3: =COUNTIF(Evalucion!DF:DF,$E3)/DF$7 -> 0 | DG3: =COUNTIF(Evalucion!DG:DG,$E3)/DG$7 -> 0.02 | DH3: =COUNTIF(Evalucion!DH:DH,$E3)/DH$7 -> 0 | DI3: =COUNTIF(Evalucion!DI:DI,$E3)/DI$7 -> 0.7 | DJ3: =COUNTIF(Evalucion!DJ:DJ,$E3)/DJ$7 -> 0 | DK3: =COUNTIF(Evalucion!DK:DK,$E3)/DK$7 -> 0.72 | DL3: =COUNTIF(Evalucion!DL:DL,$E3)/DL$7 -> 0 | DM3: =COUNTIF(Evalucion!DM:DM,$E3)/DM$7 -> 0.48 | DN3: =COUNTIF(Evalucion!DN:DN,$E3)/DN$7 -> 0 | DO3: =COUNTIF(Evalucion!DO:DO,$E3)/DO$7 -> 0 | DP3: =COUNTIF(Evalucion!DP:DP,$E3)/DP$7 -> 0 | DQ3: =COUNTIF(Evalucion!DQ:DQ,$E3)/DQ$7 -> 0.16 | DR3: =COUNTIF(Evalucion!DR:DR,$E3)/DR$7 -> 0 | DS3: =COUNTIF(Evalucion!DS:DS,$E3)/DS$7 -> 0.46 | DT3: =COUNTIF(Evalucion!DT:DT,$E3)/DT$7 -> 0 | DU3: =COUNTIF(Evalucion!DU:DU,$E3)/DU$7 -> 0.16 | DV3: =COUNTIF(Evalucion!DV:DV,$E3)/DV$7 -> 0 | DW3: =COUNTIF(Evalucion!DW:DW,$E3)/DW$7 -> 0.46 | DX3: =COUNTIF(Evalucion!DX:DX,$E3)/DX$7 -> 0 | DY3: =COUNTIF(Evalucion!DY:DY,$E3)/DY$7 -> 0.46 | DZ3: =COUNTIF(Evalucion!DZ:DZ,$E3)/DZ$7 -> 0 | EA3: =COUNTIF(Evalucion!EA:EA,$E3)/EA$7 -> 0 | EB3: =COUNTIF(Evalucion!EB:EB,$E3)/EB$7 -> 0 | EC3: =COUNTIF(Evalucion!EC:EC,$E3)/EC$7 -> 0.2 | ED3: =COUNTIF(Evalucion!ED:ED,$E3)/ED$7 -> 0 | EE3: =COUNTIF(Evalucion!EE:EE,$E3)/EE$7 -> 0 | EF3: =COUNTIF(Evalucion!EF:EF,$E3)/EF$7 -> 0 | EG3: =COUNTIF(Evalucion!EG:EG,$E3)/EG$7 -> 0.12 | EH3: =COUNTIF(Evalucion!EH:EH,$E3)/EH$7 -> 0 | EI3: =COUNTIF(Evalucion!EI:EI,$E3)/EI$7 -> 0.42 | EJ3: =COUNTIF(Evalucion!EJ:EJ,$E3)/EJ$7 -> 0 | EK3: =COUNTIF(Evalucion!EK:EK,$E3)/EK$7 -> 0.32 | EL3: =COUNTIF(Evalucion!EL:EL,$E3)/EL$7 -> 0 | EM3: =COUNTIF(Evalucion!EM:EM,$E3)/EM$7 -> 0.12 | EN3: =COUNTIF(Evalucion!EN:EN,$E3)/EN$7 -> 0 | EO3: =COUNTIF(Evalucion!EO:EO,$E3)/EO$7 -> 0.52 | EP3: =COUNTIF(Evalucion!EP:EP,$E3)/EP$7 -> 0 | EQ3: =COUNTIF(Evalucion!EQ:EQ,$E3)/EQ$7 -> 0.52 | ER3: =COUNTIF(Evalucion!ER:ER,$E3)/ER$7 -> 0 | ES3: =COUNTIF(Evalucion!ES:ES,$E3)/ES$7 -> 0 | ET3: =COUNTIF(Evalucion!ET:ET,$E3)/ET$7 -> 0 | EU3: =COUNTIF(Evalucion!EU:EU,$E3)/EU$7 -> 0.02 | EV3: =COUNTIF(Evalucion!EV:EV,$E3)/EV$7 -> 0 | EW3: =COUNTIF(Evalucion!EW:EW,$E3)/EW$7 -> 0 | EX3: =COUNTIF(Evalucion!EX:EX,$E3)/EX$7 -> 0 | EY3: =COUNTIF(Evalucion!EY:EY,$E3)/EY$7 -> 0 | EZ3: =COUNTIF(Evalucion!EZ:EZ,$E3)/EZ$7 -> 0
E4: Confiable | F4: =COUNTIF(Evalucion!F:F,$E4)/F$7 -> 0 | G4: =COUNTIF(Evalucion!G:G,$E4)/G$7 -> 0.84 | H4: =COUNTIF(Evalucion!H:H,$E4)/H$7 -> 0 | I4: =COUNTIF(Evalucion!I:I,$E4)/I$7 -> 0.3 | J4: =COUNTIF(Evalucion!J:J,$E4)/J$7 -> 0 | K4: =COUNTIF(Evalucion!K:K,$E4)/K$7 -> 0.22 | L4: =COUNTIF(Evalucion!L:L,$E4)/L$7 -> 0 | M4: =COUNTIF(Evalucion!M:M,$E4)/M$7 -> 0.82 | N4: =COUNTIF(Evalucion!N:N,$E4)/N$7 -> 0 | O4: =COUNTIF(Evalucion!O:O,$E4)/O$7 -> 0.8 | P4: =COUNTIF(Evalucion!P:P,$E4)/P$7 -> 0 | Q4: =COUNTIF(Evalucion!Q:Q,$E4)/Q$7 -> 0.54 | R4: =COUNTIF(Evalucion!R:R,$E4)/R$7 -> 0 | S4: =COUNTIF(Evalucion!S:S,$E4)/S$7 -> 0.8 | T4: =COUNTIF(Evalucion!T:T,$E4)/T$7 -> 0 | U4: =COUNTIF(Evalucion!U:U,$E4)/U$7 -> 0.64 | V4: =COUNTIF(Evalucion!V:V,$E4)/V$7 -> 0 | W4: =COUNTIF(Evalucion!W:W,$E4)/W$7 -> 0.66 | X4: =COUNTIF(Evalucion!X:X,$E4)/X$7 -> 0 | Y4: =COUNTIF(Evalucion!Y:Y,$E4)/Y$7 -> 0.64 | Z4: =COUNTIF(Evalucion!Z:Z,$E4)/Z$7 -> 0 | AA4: =COUNTIF(Evalucion!AA:AA,$E4)/AA$7 -> 0.66 | AB4: =COUNTIF(Evalucion!AB:AB,$E4)/AB$7 -> 0 | AC4: =COUNTIF(Evalucion!AC:AC,$E4)/AC$7 -> 0.64 | AD4: =COUNTIF(Evalucion!AD:AD,$E4)/AD$7 -> 0 | AE4: =COUNTIF(Evalucion!AE:AE,$E4)/AE$7 -> 0.3 | AF4: =COUNTIF(Evalucion!AF:AF,$E4)/AF$7 -> 0 | AG4: =COUNTIF(Evalucion!AG:AG,$E4)/AG$7 -> 0.8 | AH4: =COUNTIF(Evalucion!AH:AH,$E4)/AH$7 -> #DIV/0! | AI4: =COUNTIF(Evalucion!AI:AI,$E4)/AI$7 -> #DIV/0! | AJ4: =COUNTIF(Evalucion!AJ:AJ,$E4)/AJ$7 -> #DIV/0! | AK4: =COUNTIF(Evalucion!AK:AK,$E4)/AK$7 -> #DIV/0! | AL4: =COUNTIF(Evalucion!AL:AL,$E4)/AL$7 -> #DIV/0! | AM4: =COUNTIF(Evalucion!AM:AM,$E4)/AM$7 -> #DIV/0! | AN4: =COUNTIF(Evalucion!AN:AN,$E4)/AN$7 -> #DIV/0! | AO4: =COUNTIF(Evalucion!AO:AO,$E4)/AO$7 -> #DIV/0! | AP4: =COUNTIF(Evalucion!AP:AP,$E4)/AP$7 -> 0 | AQ4: =COUNTIF(Evalucion!AQ:AQ,$E4)/AQ$7 -> 0.26 | AR4: =COUNTIF(Evalucion!AR:AR,$E4)/AR$7 -> 0 | AS4: =COUNTIF(Evalucion!AS:AS,$E4)/AS$7 -> 0.12 | AT4: =COUNTIF(Evalucion!AT:AT,$E4)/AT$7 -> 0 | AU4: =COUNTIF(Evalucion!AU:AU,$E4)/AU$7 -> 0.64 | AV4: =COUNTIF(Evalucion!AV:AV,$E4)/AV$7 -> #DIV/0! | AW4: =COUNTIF(Evalucion!AW:AW,$E4)/AW$7 -> 0 | AX4: =COUNTIF(Evalucion!AX:AX,$E4)/AX$7 -> 0.44 | AY4: =COUNTIF(Evalucion!AY:AY,$E4)/AY$7 -> 0 | AZ4: =COUNTIF(Evalucion!AZ:AZ,$E4)/AZ$7 -> 0.9 | BA4: =COUNTIF(Evalucion!BA:BA,$E4)/BA$7 -> 0 | BB4: =COUNTIF(Evalucion!BB:BB,$E4)/BB$7 -> 1 | BC4: =COUNTIF(Evalucion!BC:BC,$E4)/BC$7 -> 0 | BD4: =COUNTIF(Evalucion!BD:BD,$E4)/BD$7 -> 0.26 | BE4: =COUNTIF(Evalucion!BE:BE,$E4)/BE$7 -> 0 | BF4: =COUNTIF(Evalucion!BF:BF,$E4)/BF$7 -> 0.26 | BG4: =COUNTIF(Evalucion!BG:BG,$E4)/BG$7 -> 0 | BH4: =COUNTIF(Evalucion!BH:BH,$E4)/BH$7 -> 1 | BI4: =COUNTIF(Evalucion!BI:BI,$E4)/BI$7 -> 0 | BJ4: =COUNTIF(Evalucion!BJ:BJ,$E4)/BJ$7 -> 0.7 | BK4: =COUNTIF(Evalucion!BK:BK,$E4)/BK$7 -> 0 | BL4: =COUNTIF(Evalucion!BL:BL,$E4)/BL$7 -> 0.58 | BM4: =COUNTIF(Evalucion!BM:BM,$E4)/BM$7 -> 0 | BN4: =COUNTIF(Evalucion!BN:BN,$E4)/BN$7 -> 0.56 | BO4: =COUNTIF(Evalucion!BO:BO,$E4)/BO$7 -> 0 | BP4: =COUNTIF(Evalucion!BP:BP,$E4)/BP$7 -> 0.9 | BQ4: =COUNTIF(Evalucion!BQ:BQ,$E4)/BQ$7 -> 0 | BR4: =COUNTIF(Evalucion!BR:BR,$E4)/BR$7 -> 0.32 | BS4: =COUNTIF(Evalucion!BS:BS,$E4)/BS$7 -> 0 | BT4: =COUNTIF(Evalucion!BT:BT,$E4)/BT$7 -> 0.24 | BU4: =COUNTIF(Evalucion!BU:BU,$E4)/BU$7 -> 0 | BV4: =COUNTIF(Evalucion!BV:BV,$E4)/BV$7 -> 0.28 | BW4: =COUNTIF(Evalucion!BW:BW,$E4)/BW$7 -> 0 | BX4: =COUNTIF(Evalucion!BX:BX,$E4)/BX$7 -> 0.9 | BY4: =COUNTIF(Evalucion!BY:BY,$E4)/BY$7 -> 0 | BZ4: =COUNTIF(Evalucion!BZ:BZ,$E4)/BZ$7 -> 0.7 | CA4: =COUNTIF(Evalucion!CA:CA,$E4)/CA$7 -> 0 | CB4: =COUNTIF(Evalucion!CB:CB,$E4)/CB$7 -> 0.62 | CC4: =COUNTIF(Evalucion!CC:CC,$E4)/CC$7 -> 0 | CD4: =COUNTIF(Evalucion!CD:CD,$E4)/CD$7 -> 0.9 | CE4: =COUNTIF(Evalucion!CE:CE,$E4)/CE$7 -> 0 | CF4: =COUNTIF(Evalucion!CF:CF,$E4)/CF$7 -> 0.16 | CG4: =COUNTIF(Evalucion!CG:CG,$E4)/CG$7 -> 0 | CH4: =COUNTIF(Evalucion!CH:CH,$E4)/CH$7 -> 0.14 | CI4: =COUNTIF(Evalucion!CI:CI,$E4)/CI$7 -> 0 | CJ4: =COUNTIF(Evalucion!CJ:CJ,$E4)/CJ$7 -> 0.22 | CK4: =COUNTIF(Evalucion!CK:CK,$E4)/CK$7 -> 0 | CL4: =COUNTIF(Evalucion!CL:CL,$E4)/CL$7 -> 0.9 | CM4: =COUNTIF(Evalucion!CM:CM,$E4)/CM$7 -> 0 | CN4: =COUNTIF(Evalucion!CN:CN,$E4)/CN$7 -> 0.54 | CO4: =COUNTIF(Evalucion!CO:CO,$E4)/CO$7 -> 0 | CP4: =COUNTIF(Evalucion!CP:CP,$E4)/CP$7 -> 1 | CQ4: =COUNTIF(Evalucion!CQ:CQ,$E4)/CQ$7 -> 0 | CR4: =COUNTIF(Evalucion!CR:CR,$E4)/CR$7 -> 0.12 | CS4: =COUNTIF(Evalucion!CS:CS,$E4)/CS$7 -> 0 | CT4: =COUNTIF(Evalucion!CT:CT,$E4)/CT$7 -> 0.24 | CU4: =COUNTIF(Evalucion!CU:CU,$E4)/CU$7 -> 0 | CV4: =COUNTIF(Evalucion!CV:CV,$E4)/CV$7 -> 0.12 | CW4: =COUNTIF(Evalucion!CW:CW,$E4)/CW$7 -> 0 | CX4: =COUNTIF(Evalucion!CX:CX,$E4)/CX$7 -> 0.26 | CY4: =COUNTIF(Evalucion!CY:CY,$E4)/CY$7 -> 0 | CZ4: =COUNTIF(Evalucion!CZ:CZ,$E4)/CZ$7 -> 0.26 | DA4: =COUNTIF(Evalucion!DA:DA,$E4)/DA$7 -> 0 | DB4: =COUNTIF(Evalucion!DB:DB,$E4)/DB$7 -> 0.06 | DC4: =COUNTIF(Evalucion!DC:DC,$E4)/DC$7 -> 0 | DD4: =COUNTIF(Evalucion!DD:DD,$E4)/DD$7 -> 0.9 | DE4: =COUNTIF(Evalucion!DE:DE,$E4)/DE$7 -> 0 | DF4: =COUNTIF(Evalucion!DF:DF,$E4)/DF$7 -> 0.1 | DG4: =COUNTIF(Evalucion!DG:DG,$E4)/DG$7 -> 0 | DH4: =COUNTIF(Evalucion!DH:DH,$E4)/DH$7 -> 0.62 | DI4: =COUNTIF(Evalucion!DI:DI,$E4)/DI$7 -> 0 | DJ4: =COUNTIF(Evalucion!DJ:DJ,$E4)/DJ$7 -> 0.26 | DK4: =COUNTIF(Evalucion!DK:DK,$E4)/DK$7 -> 0 | DL4: =COUNTIF(Evalucion!DL:DL,$E4)/DL$7 -> 0.24 | DM4: =COUNTIF(Evalucion!DM:DM,$E4)/DM$7 -> 0 | DN4: =COUNTIF(Evalucion!DN:DN,$E4)/DN$7 -> 0.26 | DO4: =COUNTIF(Evalucion!DO:DO,$E4)/DO$7 -> 0 | DP4: =COUNTIF(Evalucion!DP:DP,$E4)/DP$7 -> 0.58 | DQ4: =COUNTIF(Evalucion!DQ:DQ,$E4)/DQ$7 -> 0 | DR4: =COUNTIF(Evalucion!DR:DR,$E4)/DR$7 -> 0.18 | DS4: =COUNTIF(Evalucion!DS:DS,$E4)/DS$7 -> 0 | DT4: =COUNTIF(Evalucion!DT:DT,$E4)/DT$7 -> 0.12 | DU4: =COUNTIF(Evalucion!DU:DU,$E4)/DU$7 -> 0 | DV4: =COUNTIF(Evalucion!DV:DV,$E4)/DV$7 -> 0.34 | DW4: =COUNTIF(Evalucion!DW:DW,$E4)/DW$7 -> 0 | DX4: =COUNTIF(Evalucion!DX:DX,$E4)/DX$7 -> 0.32 | DY4: =COUNTIF(Evalucion!DY:DY,$E4)/DY$7 -> 0 | DZ4: =COUNTIF(Evalucion!DZ:DZ,$E4)/DZ$7 -> 0.14 | EA4: =COUNTIF(Evalucion!EA:EA,$E4)/EA$7 -> 0 | EB4: =COUNTIF(Evalucion!EB:EB,$E4)/EB$7 -> 0.8 | EC4: =COUNTIF(Evalucion!EC:EC,$E4)/EC$7 -> 0 | ED4: =COUNTIF(Evalucion!ED:ED,$E4)/ED$7 -> 0.2 | EE4: =COUNTIF(Evalucion!EE:EE,$E4)/EE$7 -> 0 | EF4: =COUNTIF(Evalucion!EF:EF,$E4)/EF$7 -> 0.6 | EG4: =COUNTIF(Evalucion!EG:EG,$E4)/EG$7 -> 0 | EH4: =COUNTIF(Evalucion!EH:EH,$E4)/EH$7 -> 0.68 | EI4: =COUNTIF(Evalucion!EI:EI,$E4)/EI$7 -> 0 | EJ4: =COUNTIF(Evalucion!EJ:EJ,$E4)/EJ$7 -> 0.48 | EK4: =COUNTIF(Evalucion!EK:EK,$E4)/EK$7 -> 0 | EL4: =COUNTIF(Evalucion!EL:EL,$E4)/EL$7 -> 0.48 | EM4: =COUNTIF(Evalucion!EM:EM,$E4)/EM$7 -> 0 | EN4: =COUNTIF(Evalucion!EN:EN,$E4)/EN$7 -> 0.68 | EO4: =COUNTIF(Evalucion!EO:EO,$E4)/EO$7 -> 0 | EP4: =COUNTIF(Evalucion!EP:EP,$E4)/EP$7 -> 0.48 | EQ4: =COUNTIF(Evalucion!EQ:EQ,$E4)/EQ$7 -> 0 | ER4: =COUNTIF(Evalucion!ER:ER,$E4)/ER$7 -> 0.48 | ES4: =COUNTIF(Evalucion!ES:ES,$E4)/ES$7 -> 0 | ET4: =COUNTIF(Evalucion!ET:ET,$E4)/ET$7 -> 0.8 | EU4: =COUNTIF(Evalucion!EU:EU,$E4)/EU$7 -> 0 | EV4: =COUNTIF(Evalucion!EV:EV,$E4)/EV$7 -> 0.02 | EW4: =COUNTIF(Evalucion!EW:EW,$E4)/EW$7 -> 0 | EX4: =COUNTIF(Evalucion!EX:EX,$E4)/EX$7 -> 1 | EY4: =COUNTIF(Evalucion!EY:EY,$E4)/EY$7 -> 0 | EZ4: =COUNTIF(Evalucion!EZ:EZ,$E4)/EZ$7 -> 0.1
E5: Conf_CR | F5: =COUNTIF(Evalucion!F:F,$E5)/F$7 -> 0 | G5: =COUNTIF(Evalucion!G:G,$E5)/G$7 -> 0.04 | H5: =COUNTIF(Evalucion!H:H,$E5)/H$7 -> 0 | I5: =COUNTIF(Evalucion!I:I,$E5)/I$7 -> 0.14 | J5: =COUNTIF(Evalucion!J:J,$E5)/J$7 -> 0 | K5: =COUNTIF(Evalucion!K:K,$E5)/K$7 -> 0.28 | L5: =COUNTIF(Evalucion!L:L,$E5)/L$7 -> 0 | M5: =COUNTIF(Evalucion!M:M,$E5)/M$7 -> 0.18 | N5: =COUNTIF(Evalucion!N:N,$E5)/N$7 -> 0 | O5: =COUNTIF(Evalucion!O:O,$E5)/O$7 -> 0.2 | P5: =COUNTIF(Evalucion!P:P,$E5)/P$7 -> 0 | Q5: =COUNTIF(Evalucion!Q:Q,$E5)/Q$7 -> 0.12 | R5: =COUNTIF(Evalucion!R:R,$E5)/R$7 -> 0 | S5: =COUNTIF(Evalucion!S:S,$E5)/S$7 -> 0 | T5: =COUNTIF(Evalucion!T:T,$E5)/T$7 -> 0 | U5: =COUNTIF(Evalucion!U:U,$E5)/U$7 -> 0 | V5: =COUNTIF(Evalucion!V:V,$E5)/V$7 -> 0 | W5: =COUNTIF(Evalucion!W:W,$E5)/W$7 -> 0 | X5: =COUNTIF(Evalucion!X:X,$E5)/X$7 -> 0 | Y5: =COUNTIF(Evalucion!Y:Y,$E5)/Y$7 -> 0 | Z5: =COUNTIF(Evalucion!Z:Z,$E5)/Z$7 -> 0 | AA5: =COUNTIF(Evalucion!AA:AA,$E5)/AA$7 -> 0 | AB5: =COUNTIF(Evalucion!AB:AB,$E5)/AB$7 -> 0 | AC5: =COUNTIF(Evalucion!AC:AC,$E5)/AC$7 -> 0 | AD5: =COUNTIF(Evalucion!AD:AD,$E5)/AD$7 -> 0 | AE5: =COUNTIF(Evalucion!AE:AE,$E5)/AE$7 -> 0.54 | AF5: =COUNTIF(Evalucion!AF:AF,$E5)/AF$7 -> 0 | AG5: =COUNTIF(Evalucion!AG:AG,$E5)/AG$7 -> 0 | AH5: =COUNTIF(Evalucion!AH:AH,$E5)/AH$7 -> #DIV/0! | AI5: =COUNTIF(Evalucion!AI:AI,$E5)/AI$7 -> #DIV/0! | AJ5: =COUNTIF(Evalucion!AJ:AJ,$E5)/AJ$7 -> #DIV/0! | AK5: =COUNTIF(Evalucion!AK:AK,$E5)/AK$7 -> #DIV/0! | AL5: =COUNTIF(Evalucion!AL:AL,$E5)/AL$7 -> #DIV/0! | AM5: =COUNTIF(Evalucion!AM:AM,$E5)/AM$7 -> #DIV/0! | AN5: =COUNTIF(Evalucion!AN:AN,$E5)/AN$7 -> #DIV/0! | AO5: =COUNTIF(Evalucion!AO:AO,$E5)/AO$7 -> #DIV/0! | AP5: =COUNTIF(Evalucion!AP:AP,$E5)/AP$7 -> 0 | AQ5: =COUNTIF(Evalucion!AQ:AQ,$E5)/AQ$7 -> 0.74 | AR5: =COUNTIF(Evalucion!AR:AR,$E5)/AR$7 -> 0 | AS5: =COUNTIF(Evalucion!AS:AS,$E5)/AS$7 -> 0.1 | AT5: =COUNTIF(Evalucion!AT:AT,$E5)/AT$7 -> 0 | AU5: =COUNTIF(Evalucion!AU:AU,$E5)/AU$7 -> 0.32 | AV5: =COUNTIF(Evalucion!AV:AV,$E5)/AV$7 -> #DIV/0! | AW5: =COUNTIF(Evalucion!AW:AW,$E5)/AW$7 -> 0 | AX5: =COUNTIF(Evalucion!AX:AX,$E5)/AX$7 -> 0.24 | AY5: =COUNTIF(Evalucion!AY:AY,$E5)/AY$7 -> 0 | AZ5: =COUNTIF(Evalucion!AZ:AZ,$E5)/AZ$7 -> 0 | BA5: =COUNTIF(Evalucion!BA:BA,$E5)/BA$7 -> 0 | BB5: =COUNTIF(Evalucion!BB:BB,$E5)/BB$7 -> 0 | BC5: =COUNTIF(Evalucion!BC:BC,$E5)/BC$7 -> 0 | BD5: =COUNTIF(Evalucion!BD:BD,$E5)/BD$7 -> 0.02 | BE5: =COUNTIF(Evalucion!BE:BE,$E5)/BE$7 -> 0 | BF5: =COUNTIF(Evalucion!BF:BF,$E5)/BF$7 -> 0.12 | BG5: =COUNTIF(Evalucion!BG:BG,$E5)/BG$7 -> 0 | BH5: =COUNTIF(Evalucion!BH:BH,$E5)/BH$7 -> 0 | BI5: =COUNTIF(Evalucion!BI:BI,$E5)/BI$7 -> 0 | BJ5: =COUNTIF(Evalucion!BJ:BJ,$E5)/BJ$7 -> 0.02 | BK5: =COUNTIF(Evalucion!BK:BK,$E5)/BK$7 -> 0 | BL5: =COUNTIF(Evalucion!BL:BL,$E5)/BL$7 -> 0.02 | BM5: =COUNTIF(Evalucion!BM:BM,$E5)/BM$7 -> 0 | BN5: =COUNTIF(Evalucion!BN:BN,$E5)/BN$7 -> 0.04 | BO5: =COUNTIF(Evalucion!BO:BO,$E5)/BO$7 -> 0 | BP5: =COUNTIF(Evalucion!BP:BP,$E5)/BP$7 -> 0 | BQ5: =COUNTIF(Evalucion!BQ:BQ,$E5)/BQ$7 -> 0 | BR5: =COUNTIF(Evalucion!BR:BR,$E5)/BR$7 -> 0.26 | BS5: =COUNTIF(Evalucion!BS:BS,$E5)/BS$7 -> 0 | BT5: =COUNTIF(Evalucion!BT:BT,$E5)/BT$7 -> 0.24 | BU5: =COUNTIF(Evalucion!BU:BU,$E5)/BU$7 -> 0 | BV5: =COUNTIF(Evalucion!BV:BV,$E5)/BV$7 -> 0.42 | BW5: =COUNTIF(Evalucion!BW:BW,$E5)/BW$7 -> 0 | BX5: =COUNTIF(Evalucion!BX:BX,$E5)/BX$7 -> 0.1 | BY5: =COUNTIF(Evalucion!BY:BY,$E5)/BY$7 -> 0 | BZ5: =COUNTIF(Evalucion!BZ:BZ,$E5)/BZ$7 -> 0 | CA5: =COUNTIF(Evalucion!CA:CA,$E5)/CA$7 -> 0 | CB5: =COUNTIF(Evalucion!CB:CB,$E5)/CB$7 -> 0.02 | CC5: =COUNTIF(Evalucion!CC:CC,$E5)/CC$7 -> 0 | CD5: =COUNTIF(Evalucion!CD:CD,$E5)/CD$7 -> 0.1 | CE5: =COUNTIF(Evalucion!CE:CE,$E5)/CE$7 -> 0 | CF5: =COUNTIF(Evalucion!CF:CF,$E5)/CF$7 -> 0.64 | CG5: =COUNTIF(Evalucion!CG:CG,$E5)/CG$7 -> 0 | CH5: =COUNTIF(Evalucion!CH:CH,$E5)/CH$7 -> 0.26 | CI5: =COUNTIF(Evalucion!CI:CI,$E5)/CI$7 -> 0 | CJ5: =COUNTIF(Evalucion!CJ:CJ,$E5)/CJ$7 -> 0.56 | CK5: =COUNTIF(Evalucion!CK:CK,$E5)/CK$7 -> 0 | CL5: =COUNTIF(Evalucion!CL:CL,$E5)/CL$7 -> 0 | CM5: =COUNTIF(Evalucion!CM:CM,$E5)/CM$7 -> 0 | CN5: =COUNTIF(Evalucion!CN:CN,$E5)/CN$7 -> 0.46 | CO5: =COUNTIF(Evalucion!CO:CO,$E5)/CO$7 -> 0 | CP5: =COUNTIF(Evalucion!CP:CP,$E5)/CP$7 -> 0 | CQ5: =COUNTIF(Evalucion!CQ:CQ,$E5)/CQ$7 -> 0 | CR5: =COUNTIF(Evalucion!CR:CR,$E5)/CR$7 -> 0.4 | CS5: =COUNTIF(Evalucion!CS:CS,$E5)/CS$7 -> 0 | CT5: =COUNTIF(Evalucion!CT:CT,$E5)/CT$7 -> 0.48 | CU5: =COUNTIF(Evalucion!CU:CU,$E5)/CU$7 -> 0 | CV5: =COUNTIF(Evalucion!CV:CV,$E5)/CV$7 -> 0.48 | CW5: =COUNTIF(Evalucion!CW:CW,$E5)/CW$7 -> 0 | CX5: =COUNTIF(Evalucion!CX:CX,$E5)/CX$7 -> 0.64 | CY5: =COUNTIF(Evalucion!CY:CY,$E5)/CY$7 -> 0 | CZ5: =COUNTIF(Evalucion!CZ:CZ,$E5)/CZ$7 -> 0.64 | DA5: =COUNTIF(Evalucion!DA:DA,$E5)/DA$7 -> 0 | DB5: =COUNTIF(Evalucion!DB:DB,$E5)/DB$7 -> 0.78 | DC5: =COUNTIF(Evalucion!DC:DC,$E5)/DC$7 -> 0 | DD5: =COUNTIF(Evalucion!DD:DD,$E5)/DD$7 -> 0 | DE5: =COUNTIF(Evalucion!DE:DE,$E5)/DE$7 -> 0 | DF5: =COUNTIF(Evalucion!DF:DF,$E5)/DF$7 -> 0.14 | DG5: =COUNTIF(Evalucion!DG:DG,$E5)/DG$7 -> 0 | DH5: =COUNTIF(Evalucion!DH:DH,$E5)/DH$7 -> 0.36 | DI5: =COUNTIF(Evalucion!DI:DI,$E5)/DI$7 -> 0 | DJ5: =COUNTIF(Evalucion!DJ:DJ,$E5)/DJ$7 -> 0 | DK5: =COUNTIF(Evalucion!DK:DK,$E5)/DK$7 -> 0 | DL5: =COUNTIF(Evalucion!DL:DL,$E5)/DL$7 -> 0.08 | DM5: =COUNTIF(Evalucion!DM:DM,$E5)/DM$7 -> 0 | DN5: =COUNTIF(Evalucion!DN:DN,$E5)/DN$7 -> 0.24 | DO5: =COUNTIF(Evalucion!DO:DO,$E5)/DO$7 -> 0 | DP5: =COUNTIF(Evalucion!DP:DP,$E5)/DP$7 -> 0 | DQ5: =COUNTIF(Evalucion!DQ:DQ,$E5)/DQ$7 -> 0 | DR5: =COUNTIF(Evalucion!DR:DR,$E5)/DR$7 -> 0.56 | DS5: =COUNTIF(Evalucion!DS:DS,$E5)/DS$7 -> 0 | DT5: =COUNTIF(Evalucion!DT:DT,$E5)/DT$7 -> 0.42 | DU5: =COUNTIF(Evalucion!DU:DU,$E5)/DU$7 -> 0 | DV5: =COUNTIF(Evalucion!DV:DV,$E5)/DV$7 -> 0.4 | DW5: =COUNTIF(Evalucion!DW:DW,$E5)/DW$7 -> 0 | DX5: =COUNTIF(Evalucion!DX:DX,$E5)/DX$7 -> 0.22 | DY5: =COUNTIF(Evalucion!DY:DY,$E5)/DY$7 -> 0 | DZ5: =COUNTIF(Evalucion!DZ:DZ,$E5)/DZ$7 -> 0.38 | EA5: =COUNTIF(Evalucion!EA:EA,$E5)/EA$7 -> 0 | EB5: =COUNTIF(Evalucion!EB:EB,$E5)/EB$7 -> 0 | EC5: =COUNTIF(Evalucion!EC:EC,$E5)/EC$7 -> 0 | ED5: =COUNTIF(Evalucion!ED:ED,$E5)/ED$7 -> 0.6 | EE5: =COUNTIF(Evalucion!EE:EE,$E5)/EE$7 -> 0 | EF5: =COUNTIF(Evalucion!EF:EF,$E5)/EF$7 -> 0 | EG5: =COUNTIF(Evalucion!EG:EG,$E5)/EG$7 -> 0 | EH5: =COUNTIF(Evalucion!EH:EH,$E5)/EH$7 -> 0.14 | EI5: =COUNTIF(Evalucion!EI:EI,$E5)/EI$7 -> 0 | EJ5: =COUNTIF(Evalucion!EJ:EJ,$E5)/EJ$7 -> 0.04 | EK5: =COUNTIF(Evalucion!EK:EK,$E5)/EK$7 -> 0 | EL5: =COUNTIF(Evalucion!EL:EL,$E5)/EL$7 -> 0.12 | EM5: =COUNTIF(Evalucion!EM:EM,$E5)/EM$7 -> 0 | EN5: =COUNTIF(Evalucion!EN:EN,$E5)/EN$7 -> 0.12 | EO5: =COUNTIF(Evalucion!EO:EO,$E5)/EO$7 -> 0 | EP5: =COUNTIF(Evalucion!EP:EP,$E5)/EP$7 -> 0.06 | EQ5: =COUNTIF(Evalucion!EQ:EQ,$E5)/EQ$7 -> 0 | ER5: =COUNTIF(Evalucion!ER:ER,$E5)/ER$7 -> 0 | ES5: =COUNTIF(Evalucion!ES:ES,$E5)/ES$7 -> 0 | ET5: =COUNTIF(Evalucion!ET:ET,$E5)/ET$7 -> 0 | EU5: =COUNTIF(Evalucion!EU:EU,$E5)/EU$7 -> 0 | EV5: =COUNTIF(Evalucion!EV:EV,$E5)/EV$7 -> 0.34 | EW5: =COUNTIF(Evalucion!EW:EW,$E5)/EW$7 -> 0 | EX5: =COUNTIF(Evalucion!EX:EX,$E5)/EX$7 -> 0 | EY5: =COUNTIF(Evalucion!EY:EY,$E5)/EY$7 -> 0 | EZ5: =COUNTIF(Evalucion!EZ:EZ,$E5)/EZ$7 -> 0.7
E6: NO_Conf | F6: =COUNTIF(Evalucion!F:F,$E6)/F$7 -> 0 | G6: =COUNTIF(Evalucion!G:G,$E6)/G$7 -> 0.12 | H6: =COUNTIF(Evalucion!H:H,$E6)/H$7 -> 0 | I6: =COUNTIF(Evalucion!I:I,$E6)/I$7 -> 0.56 | J6: =COUNTIF(Evalucion!J:J,$E6)/J$7 -> 0 | K6: =COUNTIF(Evalucion!K:K,$E6)/K$7 -> 0.5 | L6: =COUNTIF(Evalucion!L:L,$E6)/L$7 -> 0 | M6: =COUNTIF(Evalucion!M:M,$E6)/M$7 -> 0 | N6: =COUNTIF(Evalucion!N:N,$E6)/N$7 -> 0 | O6: =COUNTIF(Evalucion!O:O,$E6)/O$7 -> 0 | P6: =COUNTIF(Evalucion!P:P,$E6)/P$7 -> 0 | Q6: =COUNTIF(Evalucion!Q:Q,$E6)/Q$7 -> 0.34 | R6: =COUNTIF(Evalucion!R:R,$E6)/R$7 -> 0 | S6: =COUNTIF(Evalucion!S:S,$E6)/S$7 -> 0.2 | T6: =COUNTIF(Evalucion!T:T,$E6)/T$7 -> 0 | U6: =COUNTIF(Evalucion!U:U,$E6)/U$7 -> 0.36 | V6: =COUNTIF(Evalucion!V:V,$E6)/V$7 -> 0 | W6: =COUNTIF(Evalucion!W:W,$E6)/W$7 -> 0.34 | X6: =COUNTIF(Evalucion!X:X,$E6)/X$7 -> 0 | Y6: =COUNTIF(Evalucion!Y:Y,$E6)/Y$7 -> 0.36 | Z6: =COUNTIF(Evalucion!Z:Z,$E6)/Z$7 -> 0 | AA6: =COUNTIF(Evalucion!AA:AA,$E6)/AA$7 -> 0.34 | AB6: =COUNTIF(Evalucion!AB:AB,$E6)/AB$7 -> 0 | AC6: =COUNTIF(Evalucion!AC:AC,$E6)/AC$7 -> 0.36 | AD6: =COUNTIF(Evalucion!AD:AD,$E6)/AD$7 -> 0 | AE6: =COUNTIF(Evalucion!AE:AE,$E6)/AE$7 -> 0.16 | AF6: =COUNTIF(Evalucion!AF:AF,$E6)/AF$7 -> 0 | AG6: =COUNTIF(Evalucion!AG:AG,$E6)/AG$7 -> 0.2 | AH6: =COUNTIF(Evalucion!AH:AH,$E6)/AH$7 -> #DIV/0! | AI6: =COUNTIF(Evalucion!AI:AI,$E6)/AI$7 -> #DIV/0! | AJ6: =COUNTIF(Evalucion!AJ:AJ,$E6)/AJ$7 -> #DIV/0! | AK6: =COUNTIF(Evalucion!AK:AK,$E6)/AK$7 -> #DIV/0! | AL6: =COUNTIF(Evalucion!AL:AL,$E6)/AL$7 -> #DIV/0! | AM6: =COUNTIF(Evalucion!AM:AM,$E6)/AM$7 -> #DIV/0! | AN6: =COUNTIF(Evalucion!AN:AN,$E6)/AN$7 -> #DIV/0! | AO6: =COUNTIF(Evalucion!AO:AO,$E6)/AO$7 -> #DIV/0! | AP6: =COUNTIF(Evalucion!AP:AP,$E6)/AP$7 -> 0 | AQ6: =COUNTIF(Evalucion!AQ:AQ,$E6)/AQ$7 -> 0 | AR6: =COUNTIF(Evalucion!AR:AR,$E6)/AR$7 -> 0 | AS6: =COUNTIF(Evalucion!AS:AS,$E6)/AS$7 -> 0.78 | AT6: =COUNTIF(Evalucion!AT:AT,$E6)/AT$7 -> 0 | AU6: =COUNTIF(Evalucion!AU:AU,$E6)/AU$7 -> 0.04 | AV6: =COUNTIF(Evalucion!AV:AV,$E6)/AV$7 -> #DIV/0! | AW6: =COUNTIF(Evalucion!AW:AW,$E6)/AW$7 -> 0 | AX6: =COUNTIF(Evalucion!AX:AX,$E6)/AX$7 -> 0.32 | AY6: =COUNTIF(Evalucion!AY:AY,$E6)/AY$7 -> 0 | AZ6: =COUNTIF(Evalucion!AZ:AZ,$E6)/AZ$7 -> 0.1 | BA6: =COUNTIF(Evalucion!BA:BA,$E6)/BA$7 -> 0 | BB6: =COUNTIF(Evalucion!BB:BB,$E6)/BB$7 -> 0 | BC6: =COUNTIF(Evalucion!BC:BC,$E6)/BC$7 -> 0 | BD6: =COUNTIF(Evalucion!BD:BD,$E6)/BD$7 -> 0.72 | BE6: =COUNTIF(Evalucion!BE:BE,$E6)/BE$7 -> 0 | BF6: =COUNTIF(Evalucion!BF:BF,$E6)/BF$7 -> 0.62 | BG6: =COUNTIF(Evalucion!BG:BG,$E6)/BG$7 -> 0 | BH6: =COUNTIF(Evalucion!BH:BH,$E6)/BH$7 -> 0 | BI6: =COUNTIF(Evalucion!BI:BI,$E6)/BI$7 -> 0 | BJ6: =COUNTIF(Evalucion!BJ:BJ,$E6)/BJ$7 -> 0.28 | BK6: =COUNTIF(Evalucion!BK:BK,$E6)/BK$7 -> 0 | BL6: =COUNTIF(Evalucion!BL:BL,$E6)/BL$7 -> 0.4 | BM6: =COUNTIF(Evalucion!BM:BM,$E6)/BM$7 -> 0 | BN6: =COUNTIF(Evalucion!BN:BN,$E6)/BN$7 -> 0.4 | BO6: =COUNTIF(Evalucion!BO:BO,$E6)/BO$7 -> 0 | BP6: =COUNTIF(Evalucion!BP:BP,$E6)/BP$7 -> 0.1 | BQ6: =COUNTIF(Evalucion!BQ:BQ,$E6)/BQ$7 -> 0 | BR6: =COUNTIF(Evalucion!BR:BR,$E6)/BR$7 -> 0.42 | BS6: =COUNTIF(Evalucion!BS:BS,$E6)/BS$7 -> 0 | BT6: =COUNTIF(Evalucion!BT:BT,$E6)/BT$7 -> 0.52 | BU6: =COUNTIF(Evalucion!BU:BU,$E6)/BU$7 -> 0 | BV6: =COUNTIF(Evalucion!BV:BV,$E6)/BV$7 -> 0.3 | BW6: =COUNTIF(Evalucion!BW:BW,$E6)/BW$7 -> 0 | BX6: =COUNTIF(Evalucion!BX:BX,$E6)/BX$7 -> 0 | BY6: =COUNTIF(Evalucion!BY:BY,$E6)/BY$7 -> 0 | BZ6: =COUNTIF(Evalucion!BZ:BZ,$E6)/BZ$7 -> 0.3 | CA6: =COUNTIF(Evalucion!CA:CA,$E6)/CA$7 -> 0 | CB6: =COUNTIF(Evalucion!CB:CB,$E6)/CB$7 -> 0.36 | CC6: =COUNTIF(Evalucion!CC:CC,$E6)/CC$7 -> 0 | CD6: =COUNTIF(Evalucion!CD:CD,$E6)/CD$7 -> 0 | CE6: =COUNTIF(Evalucion!CE:CE,$E6)/CE$7 -> 0 | CF6: =COUNTIF(Evalucion!CF:CF,$E6)/CF$7 -> 0.2 | CG6: =COUNTIF(Evalucion!CG:CG,$E6)/CG$7 -> 0 | CH6: =COUNTIF(Evalucion!CH:CH,$E6)/CH$7 -> 0.6 | CI6: =COUNTIF(Evalucion!CI:CI,$E6)/CI$7 -> 0 | CJ6: =COUNTIF(Evalucion!CJ:CJ,$E6)/CJ$7 -> 0.22 | CK6: =COUNTIF(Evalucion!CK:CK,$E6)/CK$7 -> 0 | CL6: =COUNTIF(Evalucion!CL:CL,$E6)/CL$7 -> 0.1 | CM6: =COUNTIF(Evalucion!CM:CM,$E6)/CM$7 -> 0 | CN6: =COUNTIF(Evalucion!CN:CN,$E6)/CN$7 -> 0 | CO6: =COUNTIF(Evalucion!CO:CO,$E6)/CO$7 -> 0 | CP6: =COUNTIF(Evalucion!CP:CP,$E6)/CP$7 -> 0 | CQ6: =COUNTIF(Evalucion!CQ:CQ,$E6)/CQ$7 -> 0 | CR6: =COUNTIF(Evalucion!CR:CR,$E6)/CR$7 -> 0.48 | CS6: =COUNTIF(Evalucion!CS:CS,$E6)/CS$7 -> 0 | CT6: =COUNTIF(Evalucion!CT:CT,$E6)/CT$7 -> 0.28 | CU6: =COUNTIF(Evalucion!CU:CU,$E6)/CU$7 -> 0 | CV6: =COUNTIF(Evalucion!CV:CV,$E6)/CV$7 -> 0.4 | CW6: =COUNTIF(Evalucion!CW:CW,$E6)/CW$7 -> 0 | CX6: =COUNTIF(Evalucion!CX:CX,$E6)/CX$7 -> 0.1 | CY6: =COUNTIF(Evalucion!CY:CY,$E6)/CY$7 -> 0 | CZ6: =COUNTIF(Evalucion!CZ:CZ,$E6)/CZ$7 -> 0.1 | DA6: =COUNTIF(Evalucion!DA:DA,$E6)/DA$7 -> 0 | DB6: =COUNTIF(Evalucion!DB:DB,$E6)/DB$7 -> 0.16 | DC6: =COUNTIF(Evalucion!DC:DC,$E6)/DC$7 -> 0 | DD6: =COUNTIF(Evalucion!DD:DD,$E6)/DD$7 -> 0.1 | DE6: =COUNTIF(Evalucion!DE:DE,$E6)/DE$7 -> 0 | DF6: =COUNTIF(Evalucion!DF:DF,$E6)/DF$7 -> 0.76 | DG6: =COUNTIF(Evalucion!DG:DG,$E6)/DG$7 -> 0 | DH6: =COUNTIF(Evalucion!DH:DH,$E6)/DH$7 -> 0.02 | DI6: =COUNTIF(Evalucion!DI:DI,$E6)/DI$7 -> 0 | DJ6: =COUNTIF(Evalucion!DJ:DJ,$E6)/DJ$7 -> 0.74 | DK6: =COUNTIF(Evalucion!DK:DK,$E6)/DK$7 -> 0 | DL6: =COUNTIF(Evalucion!DL:DL,$E6)/DL$7 -> 0.68 | DM6: =COUNTIF(Evalucion!DM:DM,$E6)/DM$7 -> 0 | DN6: =COUNTIF(Evalucion!DN:DN,$E6)/DN$7 -> 0.5 | DO6: =COUNTIF(Evalucion!DO:DO,$E6)/DO$7 -> 0 | DP6: =COUNTIF(Evalucion!DP:DP,$E6)/DP$7 -> 0.42 | DQ6: =COUNTIF(Evalucion!DQ:DQ,$E6)/DQ$7 -> 0 | DR6: =COUNTIF(Evalucion!DR:DR,$E6)/DR$7 -> 0.26 | DS6: =COUNTIF(Evalucion!DS:DS,$E6)/DS$7 -> 0 | DT6: =COUNTIF(Evalucion!DT:DT,$E6)/DT$7 -> 0.46 | DU6: =COUNTIF(Evalucion!DU:DU,$E6)/DU$7 -> 0 | DV6: =COUNTIF(Evalucion!DV:DV,$E6)/DV$7 -> 0.26 | DW6: =COUNTIF(Evalucion!DW:DW,$E6)/DW$7 -> 0 | DX6: =COUNTIF(Evalucion!DX:DX,$E6)/DX$7 -> 0.46 | DY6: =COUNTIF(Evalucion!DY:DY,$E6)/DY$7 -> 0 | DZ6: =COUNTIF(Evalucion!DZ:DZ,$E6)/DZ$7 -> 0.48 | EA6: =COUNTIF(Evalucion!EA:EA,$E6)/EA$7 -> 0 | EB6: =COUNTIF(Evalucion!EB:EB,$E6)/EB$7 -> 0.2 | EC6: =COUNTIF(Evalucion!EC:EC,$E6)/EC$7 -> 0 | ED6: =COUNTIF(Evalucion!ED:ED,$E6)/ED$7 -> 0.2 | EE6: =COUNTIF(Evalucion!EE:EE,$E6)/EE$7 -> 0 | EF6: =COUNTIF(Evalucion!EF:EF,$E6)/EF$7 -> 0.4 | EG6: =COUNTIF(Evalucion!EG:EG,$E6)/EG$7 -> 0 | EH6: =COUNTIF(Evalucion!EH:EH,$E6)/EH$7 -> 0.18 | EI6: =COUNTIF(Evalucion!EI:EI,$E6)/EI$7 -> 0 | EJ6: =COUNTIF(Evalucion!EJ:EJ,$E6)/EJ$7 -> 0.48 | EK6: =COUNTIF(Evalucion!EK:EK,$E6)/EK$7 -> 0 | EL6: =COUNTIF(Evalucion!EL:EL,$E6)/EL$7 -> 0.4 | EM6: =COUNTIF(Evalucion!EM:EM,$E6)/EM$7 -> 0 | EN6: =COUNTIF(Evalucion!EN:EN,$E6)/EN$7 -> 0.2 | EO6: =COUNTIF(Evalucion!EO:EO,$E6)/EO$7 -> 0 | EP6: =COUNTIF(Evalucion!EP:EP,$E6)/EP$7 -> 0.46 | EQ6: =COUNTIF(Evalucion!EQ:EQ,$E6)/EQ$7 -> 0 | ER6: =COUNTIF(Evalucion!ER:ER,$E6)/ER$7 -> 0.52 | ES6: =COUNTIF(Evalucion!ES:ES,$E6)/ES$7 -> 0 | ET6: =COUNTIF(Evalucion!ET:ET,$E6)/ET$7 -> 0.2 | EU6: =COUNTIF(Evalucion!EU:EU,$E6)/EU$7 -> 0 | EV6: =COUNTIF(Evalucion!EV:EV,$E6)/EV$7 -> 0.64 | EW6: =COUNTIF(Evalucion!EW:EW,$E6)/EW$7 -> 0 | EX6: =COUNTIF(Evalucion!EX:EX,$E6)/EX$7 -> 0 | EY6: =COUNTIF(Evalucion!EY:EY,$E6)/EY$7 -> 0 | EZ6: =COUNTIF(Evalucion!EZ:EZ,$E6)/EZ$7 -> 0.2
